Workbook

Sheet Instructions
A1: How to use the Test Log
A2: Enter one test per row on the 'Test Log' sheet. The Summary and Weekly Summary sheets calculate automatically from those entries.
A3: Use the drop-down lists for Week, Product, Translation Result, IWXXM Validation, Accuracy and Severity to ensure the formulas count results consistently.
A4: For a failed or questionable result, also complete an Error Report and reference the file/screenshot in the Test Log.

Sheet Test Log
A1: Test ID | B1: Week | C1: Date | D1: Product | E1: TAC Message / Reference | F1: Translation Result | G1: IWXXM Validation | H1: TAC vs IWXXM Accurate? | I1: Severity | J1: Issue / Comment | K1: Screenshot / File Reference | L1: Retest Result
A2: T001(EXAMPLE-See Instructions Sheet) | B2: Week 1 | C2: 46273 | D2: METAR | E2: SAGY31 SYCJ 081700 METAR SYCJ 081700Z 36006KT 280V010 9999 FEW018CB BKN022 33/24 Q1012 NOSIG RMK CB SSE-N= | F2: PASS | G2: FAIL | H2: NO | I2: MAJOR | J2: METAR converted to IWXXM and core meteorological elements were represented. IWXXM validation returned “Invalid – IWXXM 2025-2” with AIRPORT_ICAO and TAC_SYNTAX failures. Generated issue/observation time was 2023-06-08T17:00Z while the bulletin identifier contained 20260908170000. | K2: METAR-1-IWXXM-CONVERT METAR-1-IWXXM-VALIDATE | L2: SAME RESULT
A3: T002 | B3: Week 1 | D3: METAR | E3: SAGY31 SYCJ 081600 METAR SYCJ 081600Z 09010KT 360V100 9999 VCSH FEW018CB BKN019 BKN100 33/24 Q1013 NOSIG RMK CB SW-N VCSH W= | F3: FAIL | G3: FAIL | H3: UNCERTAIN | J3: The converter rejected the SYCJ 081600Z METAR because VCSH was identified as an invalid present-weather token. No IWXXM output was generated. | K3: METAR-2-IWXXM-CONVERT | L3: SAME RESULT
A4: T003 | B4: Week 1 | D4: METAR | E4: SAGY31 SYCJ 081300 METAR SYCJ 081300Z VRB02KT 9999 SCT018 BKN100 31/26 Q1015 NOSIG= | F4: PASS | G4: FAIL | H4: NO | I4: Major | J4: METAR converted successfully and core meteorological elements were accurately represented in IWXXM. Validation returned “Invalid – IWXXM 2025-2” with AIRPORT_ICAO and TAC_SYNTAX failures. IWXXM issue/observation time was 2023-06-08T13:00Z while the bulletin identifier contained 20260908130000. Similar date/validation behaviour was observed in T001. | K4: METAR-3-IWXXM-CONVERT METAR-3-IWXXM-VALIDATE | L4: SAME RESULT
A5: T004 | B5: Week 1 | D5: METAR | E5: SAGY31 SYCJ 080200 METAR SYCJ 080200Z 05004KT 9999 FEW016 26/25 Q1013 NOSIG= | F5: PASS | G5: FAIL | H5: NO | I5: Major | J5: METAR converted successfully and all core meteorological elements were accurately represented in IWXXM. Validation returned “Invalid – IWXXM 2025-2” with AIRPORT_ICAO and TAC_SYNTAX failures. IWXXM issue/observation time was generated as 2023-06-08T02:00Z while the bulletin identifier contained 20260908020000. This repeats the date/validation behaviour observed in previous METAR tests. | K5: METAR-4-IWXXM-CONVERT METAR-4-IWXXM-VALIDATE | L5: SAME RESULT
A6: T005 | B6: Week 1 | D6: METAR | E6: SAGY31 SYCJ 072000 METAR SYCJ 072000Z 07012KT 9999 SCT020 32/25 Q1010 NOSIG= | F6: PASS | G6: FAIL | H6: NO | I6: Major | J6: METAR converted successfully and the core meteorological elements were accurately represented in IWXXM. Validation returned “Invalid – IWXXM 2025-2” with AIRPORT_ICAO and TAC_SYNTAX failures. The generated IWXXM issue/observation time was 2023-06-07T20:00Z, while the bulletin identifier contained 20260907200000. This repeats the validation and date behaviour identified in previous METAR tests. | K6: METAR-5-IWXXM-CONVERT METAR-5-IWXXM-VALIDATE | L6: SAME RESULT
A7: T006 | B7: Week 1 | D7: METAR | E7: SAGY31 SYCJ 071000 METAR SYCJ 071000Z 00000KT 7000 FEW018 25/25 Q1012 NOSIG= | F7: PASS | G7: FAIL | H7: NO | I7: Major | J7: METAR converted successfully with the principal meteorological elements represented in IWXXM. Validation returned “Invalid – IWXXM 2025-2” with AIRPORT_ICAO and TAC_SYNTAX failures. The generated issue/observation time was 2023-06-07T10:00Z while the bulletin identifier contained 20260907100000, reproducing the previously identified date discrepancy. Calm wind (00000KT) was represented as mean wind direction 0° and mean wind speed 0 kt and should be verified against the applicable IWXXM 2025-2 encoding requirements. | K7: METAR-6-IWXXM-CONVERT METAR-6-IWXXM-VALIDATE
A8: T007 | B8: Week 1 | D8: METAR | E8: SAGY31 SYCJ 050600 METAR SYCJ 050600Z COR 10004KT 9999 FEW014 25/25 Q1011 NOSIG= | F8: PASS | G8: FAIL | H8: NO | I8: Major | J8: The application labels the product “Invalid — IWXXM 2025-2”. Separately, the generated product exhibits a date inconsistency, and the TAC COR modifier appears not to be reflected in the generated IWXXM report status. | K8: METAR-7-IWXXM-CONVERT METAR-7-IWXXM-VALIDATE
A9: T008 | B9: Week 1 | D9: METAR | E9: SAGY31 SYCJ 051000 METAR SYCJ 051000Z 00000KT 0700 FG BKN001 23/23 Q1012 NOSIG= | F9: PASS | G9: FAIL | H9: NO | I9: Major | J9: The converter successfully encoded and subsequently decoded the METAR containing calm wind, 700 m prevailing visibility, fog (FG), BKN cloud at 100 ft, temperature/dew point, QNH and NOSIG without apparent loss of the meteorological information. However, a significant temporal inconsistency remains: issueTime and observationTime are encoded as 2023-06-05T10:00:00Z, whereas the bulletin identifier contains 20260905100000. The validation interface additionally reports AIRPORT_ICAO and TAC_SYNTAX failures despite successfully identifying SYCJ and decoding the IWXXM content. | K9: METAR-8-IWXXM-CONVERT METAR-8-IWXXM-VALIDATE
A10: T009 | B10: Week 1 | D10: SPECI | E10: SATD31 TTPP 080020 SPECI TTPP 080020Z 11003KT 7000 FEW015 28/22 Q1014 NOSIG= | F10: PASS | G10: NOT TESTED | H10: UNCERTAIN | I10: Major | J10: The application successfully decodes the SPECI report SPECI TTPP 080020Z 11003KT 7000 FEW015 28/22 Q1014 NOSIG= but treats the supplied abbreviated heading SATD31 TTPP 080020 as residual text and subsequently rejects conversion with the message “The abbreviated heading is not valid.” | K10: SPECI-1-IWXXM-CONVERT
A11: T010 | B11: Week 1 | D11: SPECI | E11: SAAT31 TUPJ 071734 SPECI TUPJ 071734Z 12007KT 10SM TS VCSH FEW012CB SCT017 30/25 A3000 RMK Q1015 VIS16KM= | F11: PASS | G11: NOT TESTED | H11: UNCERTAIN | I11: Major | J11: This test reveals two separate issues: the bulletin/AHL problem is still preventing conversion, and the SPECI decoder is also leaving legitimate weather information as residuals. | K11: SPECI-2-IWXXM-CONVERT
A12: T011 | B12: Week 1 | D12: SPECI | E12: SABR31 TBPB 081538 SPECI TBPB 081538Z 07015KT 9999 -SHRA VCSH SCT010CB SCT014 28/26 Q1015 RETSRA NOSIG= | F12: PASS | G12: NOT TESTED | H12: UNCERTAIN | I12: Major | J12: This test confirms the same AHL parsing failure, while also exposing two missing SPECI weather groups in the decoder. | K12: SPECI-3-IWXXM-CONVERT
A13: T012 | B13: Week 1 | D13: TAF | E13: FTCA31 TTPP 081600 TAF TTPP 081600Z 0818/0918 10012KT 9999 SCT022 BECMG 0900/0902 08005KT FEW018 SCT040 PROB40 TEMPO VRB10G20KT 7000 SHRA FEW012CB BKN015 BECMG 0912/0914 12014KT SCT016 SCT045= | F13: PASS | G13: FAIL | H13: NO | I13: Critical | J13: PROB40 TEMPO incorrectly encoded. The TAC contains PROB40 TEMPO VRB10G20KT 7000 SHRA FEW012CB BKN015, but the generated IWXXM does not preserve this as a separate PROB40/TEMPO change forecast. Instead, 7000 m, SHRA, FEW012CB and BKN015 are incorrectly incorporated into the preceding BECMG 0900/0902 forecast. The VRB10G20KT wind is also missing from the generated change forecast. Validation additionally reports AIRPORT_ICAO and TAC_SYNTAX. | K13: T012A T012B
A14: T013 | B14: Week 1 | D14: TAF | E14: FTCA31 TTPP 081600 TAF TTCP 081600Z 0818/0918 10014KT 9999 SCT022 BECMG 0900/0902 08008KT FEW015 SCT040 TEMPO VRB12G22KT 6000 SHRA FEW012CB BKN015 BECMG 0912/0914 12015KT SCT016 SCT045= | F14: FAIL | G14: FAIL | H14: NO | I14: Critical | J14: TAF TEMPO change group is recognized by the TAC parser but incorrectly encoded during IWXXM generation. TEMPO conditions (VRB12G22KT 6000 SHRA FEW012CB BKN015) are merged into the preceding BECMG group; the TEMPO change forecast is absent and the TEMPO variable/gusting wind is lost. Generated IWXXM therefore does not faithfully represent the source TAC. Validation also fails AIRPORT_ICAO and TAC_SYNTAX. | K14: T013A T013B
A15: T014 | B15: Week 1 | D15: TAF | E15: FTCA32 KWBC 081100 TAF TUPJ 081100Z 0812/0912 09011KT 9999 SCT019 TEMPO 0902/0912 SHRA FEW012CB BKN014 BKN035 PROB40 TEMPO 0904/0910 4500 TSRA= | F15: FAIL | G15: FAIL | H15: NO | I15: Critical | J15: TAC contains PROB40 TEMPO 0904/0910 4500 TSRA, but the second IWXXM change forecast is encoded only as TEMPORARY_FLUCTUATIONS; the 40% probability is not represented. Validator also reports AIRPORT_ICAO and TAC_SYNTAX failures. | K15: T014A T014B
A16: T015 | B16: Week 1 | D16: TAF | E16: FTCA31 MKJP 081500 TAF MZBZ 081500Z 0818/0918 12008KT 9999 SCT024= | F16: PASS | G16: FAIL | H16: YES | I16: Critical | J16: The actual TAF translation itself appears correct. The problem is the validation stage, not the meteorological conversion. Therefore, I would not mark “TAC vs IWXXM Accurate?” as NO for this test. The IWXXM correctly carries the TAF information, but the system still returns Invalid — IWXXM 2025-2 because AIRPORT_ICAO and TAC_SYNTAX failed. | K16: T015A T015B
A17: T016 | B17: Week 1 | D17: SIGMET | E17: WSCA31 TTPP 251435 TTZP SIGMET 3 VALID 251435/251835 TTPP- TTZP PIARCO FIR EMBD TS OBS AT 1410Z WI N1800 W05406 - N1800 W05039 - N1031 W05542 - N1316 W05936 - N1800 W05406 TOP ABV FL380 STNR DECR= | F17: FAIL | G17: FAIL | H17: NO | I17: Critical | J17: TAC specifies DECR (decreasing intensity), but generated IWXXM encodes intensityChange="NO_CHANGE". Other key elements including EMBD TS, OBS time, polygon coordinates, sequence number and validity period are represented. Validator also reports AIRPORT_ICAO and TAC_SYNTAX failures. | K17: T016A T016B
A18: T017 | B18: Week 1 | D18: SIGMET | E18: WSCA31 TTPP 261150 TTZP SIGMET 1 VALID 261150/261550 TTPP- TTZP PIARCO FIR EMBD TS OBS AT 1145Z WI N1800 W05839 - N1800 W05450 - N1635 W05450 - N1635 W05839 - N1800 W05839 TOP ABV FL310 MOV NW 15KT WKN = | F18: FAIL | G18: FAIL | H18: NO | I18: Critical | J18: TAC specifies TOP ABV FL310, MOV NW 15KT, and WKN. The IWXXM correctly encodes the weakening trend as intensityChange="WEAKEN" and correctly represents the polygon, phenomenon and observation time. However, the generated IWXXM does not encode the TOP ABV FL310 vertical extent or MOV NW 15KT movement. Validator also reports AIRPORT_ICAO and TAC_SYNTAX failures. | K18: T017A T017B
... A20: T019 | B20: Week 1 | D20: SIGMET | E20: WSAZ31 LPMG 182021 LPPO SIGMET T03 VALID 182030/190030 LPPT- LPPO SANTA MARIA OCEANIC FIR EMBD TS FCST WI N3514 W01656 - N3529 W01758 - N3845 W01616 - N3726 W01525 - N3628 W01526 - N3514 W01656 TOP FL380 MOV SW 25KT NC= | F20: FAIL | G20: NOT TESTED | H20: NO | I20: Critical | J20: System returned “No TAC reports found after the abbreviated heading.” The AHL WSAZ31 LPMG 182021 was entered followed by the SIGMET, but the converter failed to recognize the TAC report. Therefore, no IWXXM output was generated for comparison or validation. | K20: T019
A21: T020 | B21: Week 2 | C21: 46291 | D21: METAR | E21: SAGY31 SYCJ 260000 METAR SYCJ 260000Z 05004KT 9999 FEW018 27/26 Q1011 NOSIG= | F21: PASS | G21: FAIL | H21: YES | I21: Critical | J21: TAC-to-IWXXM translation is meteorologically accurate: SYCJ, observation time, wind 050°/4 kt, visibility 9999 m, FEW018, temperature 27°C, dewpoint 26°C, QNH 1011 hPa and NOSIG are represented. However, validation returns Invalid — IWXXM 2025-2, with AIRPORT_ICAO and TAC_SYNTAX failures. | K21: T020A T020B
A22: T021 | B22: Week 2 | D22: METAR | E22: SAGY31 SYCJ 260100 METAR SYCJ 260100Z VRB02KT 9999 FEW018 27/26 Q1012 NOSIG= | F22: PASS | G22: FAIL | H22: YES | I22: Critical | J22: TAC-to-IWXXM translation is accurate. VRB02KT is correctly represented by variableWindDirection="true" with mean wind speed 2 kt and no fixed wind direction. Visibility 9999 m, FEW018, temperature 27°C, dewpoint 26°C, QNH 1012 hPa and NOSIG are also represented. However, validation returns Invalid — IWXXM 2025-2, failing AIRPORT_ICAO and TAC_SYNTAX. | K22: T021A T021B
A23: T022 | B23: Week 2 | D23: METAR | E23: SAGY31 SYCJ 260200 METAR SYCJ 260200Z VRB02KT 9000 FEW018 27/26 Q1012 NOSIG= | F23: PASS | G23: FAIL | H23: YES | I23: Critical | J23: TAC-to-IWXXM translation is accurate. VRB02KT is correctly encoded with variableWindDirection="true" and mean wind speed 2 kt. Visibility 9000 m, FEW018, temperature 27°C, dewpoint 26°C, QNH 1012 hPa and NOSIG are correctly represented. However, validation returns Invalid — IWXXM 2025-2, failing AIRPORT_ICAO and TAC_SYNTAX. | K23: T022A T022B
A24: T023 | B24: Week 2 | D24: METAR | E24: SAGY31 SYCJ 260300 METAR SYCJ 260300Z VRB02KT 9000 FEW018 27/26 Q1012 NOSIG= | F24: PASS | G24: FAIL | H24: YES | I24: Critical | J24: TAC-to-IWXXM translation is accurate. VRB02KT is correctly encoded with variableWindDirection="true" and mean wind speed 2 kt. Visibility 9000 m, FEW018, temperature 27°C, dewpoint 26°C, QNH 1012 hPa and NOSIG are correctly represented. However, validation returns Invalid — IWXXM 2025-2, failing AIRPORT_ICAO and TAC_SYNTAX. | K24: T023A T023B
A25: T024 | B25: Week 2 | D25: METAR | E25: SAGY31 SYCJ 260300 METAR SYCJ 260800Z COR VRB02KT 0900 FG BKN001 24/24 Q1011 NOSIG= | F25: PASS | G25: FAIL | H25: NO | I25: Critical | J25: The main meteorological elements are correctly encoded: VRB02KT → variable wind at 2 kt; 0900 → 900 m; FG → fog; BKN001 → BKN at 100 ft; 24/24 → 24°C/24°C; QNH 1011 hPa; and NOSIG is represented. However, the source TAC is a corrected METAR (COR), while the IWXXM has reportStatus="NORMAL". The bulletin identifier also contains 260300 although the report/issue time is 260800Z. Validation additionally fails AIRPORT_ICAO and TAC_SYNTAX. | K25: T024A T024B
A26: T025 | B26: Week 2 | D26: METAR | E26: SAGY31 SYCJ 261600 METAR SYCJ 261600Z 02006KT 9999 BKN021 34/25 Q1012 NOSIG= | F26: PASS | G26: FAIL | H26: YES | I26: Critical | J26: TAC-to-IWXXM translation is accurate. Wind 02006KT is correctly encoded as 020° at 6 kt; 9999 visibility is represented as 9999 m with ABOVE operator; BKN021 is correctly encoded as BKN at 2,100 ft; temperature/dewpoint are 34°C/25°C; QNH is 1012 hPa; and NOSIG is represented. However, validation returns Invalid — IWXXM 2025-2, failing AIRPORT_ICAO and TAC_SYNTAX. | K26: T025A T025B
A27: T026 | B27: Week 2 | D27: SPECI | E27: SAGY31 SYCJ 261029 SPECI SYCJ 261029Z VRB02KT 3000 BR FEW014 25/24 Q1012 NOSIG= | F27: FAIL | G27: NOT TESTED | H27: UNCERTAIN | I27: Critical | J27: SPECI content was decoded correctly: variable wind at 2 kt, visibility 3000 m, mist, FEW at 1,400 ft, temperature/dewpoint 25°C/24°C, QNH 1012 hPa and NOSIG. However, conversion stopped because the AHL SAGY31 SYCJ 261029 was rejected as an invalid abbreviated heading. The system reports: “The abbreviated heading is not valid. Use TTAAii CCCC YYGGgg (optional BBB), then one or more TAC reports.” No IWXXM output was produced for validation. | K27: T026
A28: T027 | B28: Week 2 | D28: SPECI | E28: SAGY31 SYCJ 251624 SPECI SYCJ 251624Z 31002KT 9000 -TSRA FEW015CB BKN016 27/26 Q1013 RESHRA NOSIG RMK CB SW-E= | F28: FAIL | G28: NOT TESTED | H28: UNCERTAIN | I28: Critical | J28: Core SPECI elements were decoded correctly, including wind, visibility, -TSRA, FEW015CB, BKN016, temperature/dewpoint, QNH and NOSIG. However, RESHRA and CB SW-E remained undecoded residuals. In addition, the AHL SAGY31 SYCJ 251624 was rejected as invalid, causing conversion to stop before IWXXM generation. | K28: T027
A29: T028 | B29: Week 2 | D29: SPECI | E29: SAGY31 SYCJ 251244 SPECI SYCJ 251244Z VRB02KT 9999 TS VCSH FEW015CB BKN016 28/26 Q1013 NOSIG RMK CB & VCSH SE-SW= | F29: FAIL | G29: NOT TESTED | H29: UNCERTAIN | I29: Critical | J29: Core SPECI elements were decoded correctly, including VRB02KT, visibility, FEW015CB, BKN016, temperature/dewpoint, QNH and NOSIG. However, TS VCSH was not decoded, and CB & VCSH SE-SW remained an undecoded remark/residual. The AHL SAGY31 SYCJ 251244 was also rejected as invalid, preventing conversion and IWXXM generation. | K29: T028
A30: T029 | B30: Week 2 | D30: TAF | E30: FTGY31 SYCJ 261700 TAF SYCJ 261700Z 2718/2818 05006KT 9999 BKN022 BECMG 2622/2700 VRB02KT 9999 FEW018 TEMPO 2707/2710 00000KT 0700 FG BKN004 BECMG 2711/2713 10010KT 9999 FEW019CB SCT021= | F30: FAIL | G30: FAIL | H30: NO | I30: Critical | J30: TAF and all three change groups were generated in IWXXM. However, TAC VRB02KT in the first BECMG group was incorrectly encoded as variable wind with meanWindSpeed 0.0 m/s, instead of 2 kt. The validator also returned Invalid — IWXXM 2025-2, failing AIRPORT_ICAO and TAC_SYNTAX. | K30: T029A T029B
A31: T030 | B31: Week 2 | D31: TAF | E31: FTGY31 SYCJ 262300 TAF SYCJ 262300Z 2700/2724 VRB02KT 9999 FEW018 TEMPO 2707/2710 00000KT 0700 FG BKN004 BECMG 2711/2713 10010KT 9999 FEW019CB SCT021= | F31: FAIL | G31: FAIL | H31: NO | I31: Critical | J31: TAC VRB02KT is incorrectly converted to 0.0 m/s. Other forecast/change-group elements are substantially represented correctly. Validator also reports AIRPORT_ICAO and TAC_SYNTAX failures. | K31: T030A T030B
A32: T031 | B32: Week 2 | D32: TAF | E32: FTGY31 SYCJ 261100 TAF SYCJ 261100Z 2612/2712 10008KT 070V130 9999 SCT020 SCT100 TEMPO 2616/2620 8000 TS VCSH FEW017CB SCT038 BECMG 2700/2703 05006KT 9999 FEW018 SCT100= | F32: FAIL | G32: FAIL | H32: NO | I32: Critical | J32: Base wind, visibility, cloud, TEMPO timing/clouds and BECMG group were converted; however, 070V130 variable wind-direction range and TS VCSH weather in the TEMPO group are missing from the IWXXM. Validator also reports AIRPORT_ICAO and TAC_SYNTAX failures. | K32: T031A T031B
A33: T032 | B33: Week 2 | D33: TAF | E33: FTGY31 SYCJ 260500 TAF SYCJ 260500Z 2606/2706 VRB04KT 2000 BR SCT003 BECMG 2611/2613 10008KT 070V130 9999 SCT020 BKN100 TEMPO 2617/2622 8000 TS VCSH FEW016CB BKN036 BECMG 2700/2703 06006KT 9999 SCT017= | F33: FAIL | G33: FAIL | H33: NO | I33: Critical | J33: Base VRB04KT is incorrectly encoded as 0.0 m/s; base BR is omitted; 070V130 is omitted from the first BECMG group; and TS VCSH is omitted from the TEMPO group. Remaining principal visibility/cloud/change-period elements are represented. Validator also reports AIRPORT_ICAO and TAC_SYNTAX. | K33: T032A T032B
... A36: T035 | B36: Week 2 | D36: SIGMET | E36: WSGY31 SYCJ 251740 SYGC SIGMET A3 VALID 251740/252140 SYCJ - SYGC GEORGETOWN FIR EMBD TS OBS AT 1735Z WI N0823 W05945 - N0739 W05848 - N0700 W05914 - N0548 W05739 - N0528 W05756 - N0728 W06038 - N0823 W05945 TOP FL560 MOV W-NW NC= | F36: FAIL | G36: NOT TESTED | H36: NO | I36: Critical | J36: TAC decoder recognizes validity period, FIR, EMBD TS, OBS time, polygon coordinates, TOP FL560, MOV and NC; however, W-NW is not decoded as the movement direction and remains residual. GEORGETOWN also remains residual. Conversion then fails with “No TAC reports found after the abbreviated heading.” No IWXXM output is generated for validation or TAC-to-IWXXM comparison. | K36: T035
A37: T036 | B37: Week 2 | C37: 46292 | D37: METAR | E37: SAGY31 SYCJ 270000 METAR SYCJ 270000Z VRB02KT 9999 FEW018 27/25 Q1012 NOSIG= | F37: PASS | G37: FAIL | H37: YES | I37: Major | J37: Three issues occur: the AIRPORT_ICAO failure, the TAC_SYNTAX failure, and the 2023 vs 2026 timestamp inconsistency. | K37: T036A T036B
A38: T037 | B38: Week 2 | D38: METAR | E38: SAGY31 SYCJ 270100 METAR SYCJ 270100Z VRB02KT 9999 FEW018 27/25 Q1012 NOSIG= | F38: PASS | G38: FAIL | H38: YES | I38: Major | J38: The application explicitly reports AIRPORT_ICAO and TAC_SYNTAX. The 2023/2026 year discrepancy is also now confirmed again remain Major defect. | K38: T037A T037B
A39: T038 | B39: Week 2 | D39: METAR | E39: SAGY31 SYCJ 270300 METAR SYCJ 270300Z 00000KT 5000 BR FEW016 26/25 Q1012 NOSIG= | F39: PASS | G39: FAIL | H39: YES | I39: Major | J39: Recurring defects now remain very consistent: AIRPORT_ICAO, TAC_SYNTAX, and the 2023 vs 2026 timestamp discrepancy. | K39: T038A T038B
A40: T039 | B40: Week 2 | D40: METAR | E40: SAGY31 SYCJ 270800 METAR SYCJ 270800Z 00000KT 0700 FU BKN002 24/24 Q1011 NOSIG= | F40: PASS | G40: FAIL | H40: YES | I40: Major | J40: Recurring defects now remain very consistent: AIRPORT_ICAO, TAC_SYNTAX, and the 2023 vs 2026 timestamp discrepancy. | K40: T039A T039B
A41: T040 | B41: Week 2 | C41: 46294 | D41: METAR | E41: SAGY31 SYCJ 291100 METAR SYCJ 291100Z VRB02KT 9999 VCSH SCT019 25/25 Q1011 NOSIG RMK VCSH SW-NW= | F41: FAIL | G41: FAIL | H41: NO | I41: Major | J41: VCSH was rejected as INVALID_WEATHER and appears under Residuals, so the source TAC was not fully translated. The remarks VCSH SW-NW were also residual/not decoded. The system additionally reports NOSIG_PRESENT and WIND_VRB_OR_GUST as informational messages. Because no completed IWXXM representation is shown, TAC-to-IWXXM equivalence cannot be confirmed for this report. | K41: T040
A42: T041 | B42: Week 2 | D42: METAR | E42: SAGY31 SYCJ 291200 METAR SYCJ 291200Z VRB02KT 9999 -SHRA SCT019 SCT038 27/26 Q1012 NOSIG= | F42: PASS | G42: FAIL | H42: YES | I42: Major | J42: A useful comparison with T040 is that the converter rejected VCSH, but here it successfully recognizes and converts -SHRA into the IWXXM present-weather element. This helps narrow the weather-code handling defect specifically toward the vicinity-weather processing rather than precipitation/weather decoding generally. | K42: T041A T041B
A43: T042 | B43: Week 2 | D43: METAR | E43: SAGY31 SYCJ 291300 METAR SYCJ 291300Z 00000KT 9999 FEW019CB BKN020 29/26 Q1012 NOSIG RMK CB NNE-E, SE, WSW= | F43: PASS | G43: FAIL | H43: YES | I43: Major | J43: NOSIG - no significant change and RMK CB NNE-E, SE, WSW is not represented in the IWXXM. Critical recurring temporal defect: IWXXM issueTime and observationTime are 2023-06-29T13:00:00Z, while the bulletin identifier is dated 20260929130000. Validation reports AIRPORT_ICAO and TAC_SYNTAX. | K43: T042A T042B
...

Sheet Summary
A1: Product | B1: Messages Tested | C1: Translation PASS | D1: Validation PASS | E1: Accuracy YES | F1: Critical | G1: Major | H1: Minor
A2: METAR | B2: =COUNTIF('Test Log'!$D$2:$D$1000,A2) -> 24 | C2: =COUNTIFS('Test Log'!$D$2:$D$1000,A2,'Test Log'!$F$2:$F$1000,"PASS") -> 21 | D2: =COUNTIFS('Test Log'!$D$2:$D$1000,A2,'Test Log'!$G$2:$G$1000,"PASS") -> 0 | E2: =COUNTIFS('Test Log'!$D$2:$D$1000,A2,'Test Log'!$H$2:$H$1000,"YES") -> 12 | F2: =COUNTIFS('Test Log'!$D$2:$D$1000,A2,'Test Log'!$I$2:$I$1000,"Critical") -> 6 | G2: =COUNTIFS('Test Log'!$D$2:$D$1000,A2,'Test Log'!$I$2:$I$1000,"Major") -> 17 | H2: =COUNTIFS('Test Log'!$D$2:$D$1000,A2,'Test Log'!$I$2:$I$1000,"Minor") -> 0
A3: SPECI | B3: =COUNTIF('Test Log'!$D$2:$D$1000,A3) -> 6 | C3: =COUNTIFS('Test Log'!$D$2:$D$1000,A3,'Test Log'!$F$2:$F$1000,"PASS") -> 3 | D3: =COUNTIFS('Test Log'!$D$2:$D$1000,A3,'Test Log'!$G$2:$G$1000,"PASS") -> 0 | E3: =COUNTIFS('Test Log'!$D$2:$D$1000,A3,'Test Log'!$H$2:$H$1000,"YES") -> 0 | F3: =COUNTIFS('Test Log'!$D$2:$D$1000,A3,'Test Log'!$I$2:$I$1000,"Critical") -> 3 | G3: =COUNTIFS('Test Log'!$D$2:$D$1000,A3,'Test Log'!$I$2:$I$1000,"Major") -> 3 | H3: =COUNTIFS('Test Log'!$D$2:$D$1000,A3,'Test Log'!$I$2:$I$1000,"Minor") -> 0
A4: TAF | B4: =COUNTIF('Test Log'!$D$2:$D$1000,A4) -> 12 | C4: =COUNTIFS('Test Log'!$D$2:$D$1000,A4,'Test Log'!$F$2:$F$1000,"PASS") -> 5 | D4: =COUNTIFS('Test Log'!$D$2:$D$1000,A4,'Test Log'!$G$2:$G$1000,"PASS") -> 0 | E4: =COUNTIFS('Test Log'!$D$2:$D$1000,A4,'Test Log'!$H$2:$H$1000,"YES") -> 3 | F4: =COUNTIFS('Test Log'!$D$2:$D$1000,A4,'Test Log'!$I$2:$I$1000,"Critical") -> 8 | G4: =COUNTIFS('Test Log'!$D$2:$D$1000,A4,'Test Log'!$I$2:$I$1000,"Major") -> 4 | H4: =COUNTIFS('Test Log'!$D$2:$D$1000,A4,'Test Log'!$I$2:$I$1000,"Minor") -> 0
A5: SIGMET | B5: =COUNTIF('Test Log'!$D$2:$D$1000,A5) -> 7 | C5: =COUNTIFS('Test Log'!$D$2:$D$1000,A5,'Test Log'!$F$2:$F$1000,"PASS") -> 0 | D5: =COUNTIFS('Test Log'!$D$2:$D$1000,A5,'Test Log'!$G$2:$G$1000,"PASS") -> 0 | E5: =COUNTIFS('Test Log'!$D$2:$D$1000,A5,'Test Log'!$H$2:$H$1000,"YES") -> 0 | F5: =COUNTIFS('Test Log'!$D$2:$D$1000,A5,'Test Log'!$I$2:$I$1000,"Critical") -> 7 | G5: =COUNTIFS('Test Log'!$D$2:$D$1000,A5,'Test Log'!$I$2:$I$1000,"Major") -> 0 | H5: =COUNTIFS('Test Log'!$D$2:$D$1000,A5,'Test Log'!$I$2:$I$1000,"Minor") -> 0
A6: TOTAL | B6: =SUM(B2:B5) -> 49 | C6: =SUM(C2:C5) -> 29 | D6: =SUM(D2:D5) -> 0 | E6: =SUM(E2:E5) -> 15 | F6: =SUM(F2:F5) -> 24 | G6: =SUM(G2:G5) -> 24 | H6: =SUM(H2:H5) -> 0

Sheet Weekly Summary
A1: Week | B1: Purpose | C1: Messages Tested | D1: Translation PASS | E1: Validation PASS | F1: Accuracy YES | G1: Critical | H1: Major | I1: Minor
A2: Week 1 | B2: Familiarisation and basic functionality | C2: =COUNTIF('Test Log'!$B$2:$B$1000,A2) -> 19 | D2: =COUNTIFS('Test Log'!$B$2:$B$1000,A2,'Test Log'!$F$2:$F$1000,"PASS") -> 12 | E2: =COUNTIFS('Test Log'!$B$2:$B$1000,A2,'Test Log'!$G$2:$G$1000,"PASS") -> 0 | F2: =COUNTIFS('Test Log'!$B$2:$B$1000,A2,'Test Log'!$H$2:$H$1000,"YES") -> 1 | G2: =COUNTIFS('Test Log'!$B$2:$B$1000,A2,'Test Log'!$I$2:$I$1000,"Critical") -> 8 | H2: =COUNTIFS('Test Log'!$B$2:$B$1000,A2,'Test Log'!$I$2:$I$1000,"Major") -> 10 | I2: =COUNTIFS('Test Log'!$B$2:$B$1000,A2,'Test Log'!$I$2:$I$1000,"Minor") -> 0
A3: Week 2 | B3: Operational parallel testing | C3: =COUNTIF('Test Log'!$B$2:$B$1000,A3) -> 26 | D3: =COUNTIFS('Test Log'!$B$2:$B$1000,A3,'Test Log'!$F$2:$F$1000,"PASS") -> 14 | E3: =COUNTIFS('Test Log'!$B$2:$B$1000,A3,'Test Log'!$G$2:$G$1000,"PASS") -> 0 | F3: =COUNTIFS('Test Log'!$B$2:$B$1000,A3,'Test Log'!$H$2:$H$1000,"YES") -> 12 | G3: =COUNTIFS('Test Log'!$B$2:$B$1000,A3,'Test Log'!$I$2:$I$1000,"Critical") -> 16 | H3: =COUNTIFS('Test Log'!$B$2:$B$1000,A3,'Test Log'!$I$2:$I$1000,"Major") -> 10 | I3: =COUNTIFS('Test Log'!$B$2:$B$1000,A3,'Test Log'!$I$2:$I$1000,"Minor") -> 0
A4: Week 3 | B4: Error testing and final evaluation | C4: =COUNTIF('Test Log'!$B$2:$B$1000,A4) -> 4 | D4: =COUNTIFS('Test Log'!$B$2:$B$1000,A4,'Test Log'!$F$2:$F$1000,"PASS") -> 3 | E4: =COUNTIFS('Test Log'!$B$2:$B$1000,A4,'Test Log'!$G$2:$G$1000,"PASS") -> 0 | F4: =COUNTIFS('Test Log'!$B$2:$B$1000,A4,'Test Log'!$H$2:$H$1000,"YES") -> 2 | G4: =COUNTIFS('Test Log'!$B$2:$B$1000,A4,'Test Log'!$I$2:$I$1000,"Critical") -> 0 | H4: =COUNTIFS('Test Log'!$B$2:$B$1000,A4,'Test Log'!$I$2:$I$1000,"Major") -> 4 | I4: =COUNTIFS('Test Log'!$B$2:$B$1000,A4,'Test Log'!$I$2:$I$1000,"Minor") -> 0
